Workbook

Sheet Original_Data
A1: Original Dataset (unchanged) — store_performance
A2: 320 rows, 80 stores x 4 months (Jan-Apr 2025). Reference copy only; all analysis works from Cleaned_Data onward.
A4: store_id | B4: month | C4: region | D4: store_type | E4: marketing_spend | F4: footfall | G4: avg_discount_pct | H4: staff_count | I4: inventory_availability_pct | J4: competitor_distance_km | K4: holiday_flag | L4: customer_rating | M4: monthly_sales | N4: monthly_profit
A5: STR-1001 | B5: 45658 | C5: East | D5: Residential | E5: 70389.11 | F5: 8302 | G5: 0.042 | H5: 17 | I5: 75 | J5: 5.28 | K5: 1 | L5: 3.1 | M5: 658832.62 | N5: 84349.93
A6: STR-1001 | B6: 45689 | C6: East | D6: Residential | E6: 43827.89 | F6: 8487 | G6: 0.168 | H6: 23 | I6: 84.4 | J6: 4.31 | K6: 0 | L6: 2.8 | M6: 634436 | N6: 106130.54
A7: STR-1001 | B7: 45717 | C7: East | D7: Residential | E7: 59921.75 | F7: 9113 | G7: 0.133 | H7: 20 | I7: 88 | J7: 12 | K7: 0 | L7: 3.2 | M7: 678722.06 | N7: 101883.86
A8: STR-1001 | B8: 45748 | C8: East | D8: Residential | E8: 56856.63 | F8: 9431 | G8: 0.142 | H8: 23 | I8: 86.9 | J8: 4.97 | K8: 0 | L8: 3.4 | M8: 658920.3 | N8: 97910.37
A9: STR-1002 | B9: 45658 | C9: East | D9: High Street | E9: 48412.64 | F9: 9545 | G9: 0.231 | H9: 21 | I9: 97.6 | J9: 6.94 | K9: 1 | L9: 4.2 | M9: 741341.44 | N9: 119208.17
A10: STR-1002 | B10: 45689 | C10: East | D10: High Street | E10: 64811.21 | F10: 9792 | G10: 0.112 | H10: 20 | I10: 84.2 | J10: 2.88 | K10: 0 | L10: 4.2 | M10: 761835.34 | N10: 149602.23
A11: STR-1002 | B11: 45717 | C11: East | D11: High Street | E11: 46213.45 | F11: 10616 | G11: 0.122 | H11: 22 | I11: 85.2 | J11: 0.2 | K11: 1 | L11: 4.1 | M11: 806615.54 | N11: 131364.62
A12: STR-1002 | B12: 45748 | C12: East | D12: High Street | E12: 68148.52 | F12: 8567 | G12: 0.127 | H12: 23 | I12: 95.6 | J12: 0.8 | K12: 0 | L12: 3.9 | M12: 850164.26 | N12: 149262.75
A13: STR-1003 | B13: 45658 | C13: North | D13: Airport | E13: 71838.86 | F13: 10979 | G13: 0.215 | H13: 26 | I13: 88.6 | J13: 7.7 | K13: 1 | L13: 3.8 | M13: 930581.7 | N13: 136207.98
A14: STR-1003 | B14: 45689 | C14: North | D14: Airport | E14: 68133.44 | F14: 9459 | G14: 0.22 | H14: 21 | I14: 85 | J14: 1.91 | K14: 0 | L14: 4.2 | M14: 779010.94 | N14: 106328.09
A15: STR-1003 | B15: 45717 | C15: North | D15: Airport | E15: 34285.21 | F15: 9172 | G15: 0.213 | H15: 22 | I15: 88.3 | J15: 10.46 | K15: 1 | L15: 3.8 | M15: 723060.76 | N15: 123131.24
A16: STR-1003 | B16: 45748 | C16: North | D16: Airport | E16: 67979.88 | F16: 11230 | G16: 0.002 | H16: 28 | I16: 85.3 | J16: 7.16 | K16: 0 | L16: 3.8 | M16: 910791.94 | N16: 158891.28
... A37: STR-1009 | B37: 45658 | C37: North | D37: Residential | E37: 54597.83 | F37: 9429 | G37: 0.188 | H37: 21 | I37: 83.3 | J37: 11.71 | K37: 0 | L37: 4.2 | M37: 641865.03 | N37: 81342.58
A38: STR-1009 | B38: 45689 | C38: North | D38: Residential | E38: 73771.91 | F38: 11695 | G38: 0.07 | H38: 25 | I38: 84.7 | J38: 0.62 | K38: 0 | M38: 799477.76 | N38: 164974.41
A39: STR-1009 | B39: 45717 | C39: North | D39: Residential | E39: 74413.88 | F39: 9449 | G39: 0.039 | H39: 23 | I39: 92.1 | J39: 2.12 | K39: 0 | L39: 3.5 | M39: 798952.17 | N39: 161499.04
A40: STR-1009 | B40: 45748 | C40: North | D40: Residential | E40: 52483.77 | F40: 10453 | G40: 0.247 | H40: 25 | I40: 99 | J40: 6.31 | K40: 0 | L40: 3.6 | M40: 800979.78 | N40: 149242.27
A41: STR-1010 | B41: 45658 | C41: North | D41: Mall | E41: 75269.87 | F41: 8838 | G41: 0.092 | H41: 21 | I41: 83.1 | J41: 9.56 | K41: 1 | L41: 4.2 | M41: 820593.93 | N41: 115860.06
A42: STR-1010 | B42: 45689 | C42: North | D42: Mall | E42: 61245.41 | F42: 8156 | G42: 0.156 | H42: 19 | I42: 92.9 | J42: 9.05 | K42: 0 | L42: 3.8 | M42: 718330.53 | N42: 93247.9
A43: STR-1010 | B43: 45717 | C43: North | D43: Mall | E43: 93381.26 | F43: 7562 | G43: 0.198 | H43: 19 | I43: 82.9 | J43: 5.05 | K43: 0 | L43: 4 | M43: 736633.4 | N43: 115654.66
A44: STR-1010 | B44: 45748 | C44: North | D44: Mall | E44: 65012.19 | F44: 9598 | G44: 0.085 | H44: 24 | I44: 98.3 | J44: 0.89 | K44: 0 | L44: 3.8 | M44: 828623.85 | N44: 167320.52
A45: STR-1011 | B45: 45658 | C45: East | D45: Mall | E45: 40462.94 | F45: 3660 | G45: 0.218 | H45: 11 | I45: 95.2 | J45: 5.57 | K45: 0 | L45: 4.4 | M45: 592195.85 | N45: 92291.56
A46: STR-1011 | B46: 45689 | C46: East | D46: Mall | E46: 46123.88 | F46: 3227 | G46: 0.143 | H46: 10 | I46: 75.4 | J46: 1.06 | K46: 0 | L46: 4.4 | M46: 532644.46 | N46: 60681.32
A47: STR-1011 | B47: 45717 | C47: East | D47: Mall | E47: 68077.54 | F47: 3360 | G47: 0.128 | H47: 14 | I47: 88.2 | J47: 1.24 | K47: 1 | L47: 4 | M47: 657429.18 | N47: 88919.74
A48: STR-1011 | B48: 45748 | C48: East | D48: Mall | E48: 64882.14 | F48: 3642 | G48: 0.019 | H48: 13 | I48: 87.8 | J48: 4.52 | K48: 0 | L48: 4.2 | M48: 605178 | N48: 106958.74
A49: STR-1012 | B49: 45658 | C49: West | D49: Residential | E49: 138855.51 | F49: 5145 | G49: 0.06 | H49: 17 | I49: 88.2 | J49: 9.58 | K49: 0 | L49: 3.2 | M49: 595467.6 | N49: 104276.46
A50: STR-1012 | B50: 45689 | C50: West | D50: Residential | E50: 63630.21 | F50: 4460 | G50: 0.235 | H50: 14 | I50: 98.6 | J50: 5.52 | K50: 0 | L50: 3.5 | M50: 599603.4 | N50: 112685.12
... A75: STR-1018 | B75: 45717 | C75: East | D75: High Street | E75: 60571.82 | F75: 3193 | G75: 0.197 | H75: 7 | I75: 99 | J75: 1.43 | K75: 0 | L75: 3.2 | M75: 605023.87 | N75: 98545.81
A76: STR-1018 | B76: 45748 | C76: East | D76: High Street | E76: 55081.16 | F76: 5485 | G76: 0.036 | H76: 12 | I76: 88 | K76: 0 | L76: 3.5 | M76: 674774.09 | N76: 141917.59
A77: STR-1019 | B77: 45658 | C77: East | D77: Residential | E77: 46201.46 | F77: 5918 | G77: 0.277 | H77: 13 | I77: 78.8 | J77: 4.91 | K77: 0 | L77: 4.5 | M77: 616069.41 | N77: 54453.99
A78: STR-1019 | B78: 45689 | C78: East | D78: Residential | E78: 53762.92 | F78: 6821 | G78: 0.066 | H78: 19 | I78: 94.6 | J78: 7.03 | K78: 0 | L78: 4.4 | M78: 630829.94 | N78: 117090.02
A79: STR-1019 | B79: 45717 | C79: East | D79: Residential | E79: 70144.78 | F79: 6806 | G79: 0.178 | H79: 20 | I79: 93.1 | J79: 0.28 | K79: 1 | L79: 4.3 | M79: 788087.68 | N79: 116803.42
A80: STR-1019 | B80: 45748 | C80: East | D80: Residential | E80: 58749.63 | F80: 8252 | G80: 0.203 | H80: 20 | I80: 85.2 | J80: 3.61 | K80: 0 | L80: 4.5 | M80: 680840.36 | N80: 68007.68
A81: STR-1020 | B81: 45658 | C81: South | D81: High Street | E81: 56973.18 | F81: 6662 | G81: 0.1 | H81: 15 | I81: 77.7 | J81: 7.52 | K81: 1 | L81: 3.2 | M81: 643657.47 | N81: 87022.45
A82: STR-1020 | B82: 45689 | C82: South | D82: High Street | E82: 54872.82 | F82: 5962 | G82: 0.064 | H82: 12 | I82: 85.4 | J82: 2.58 | K82: 0 | L82: 2.9 | M82: 691112.6 | N82: 109212.83
A83: STR-1020 | B83: 45717 | C83: South | D83: High Street | E83: 80562.81 | F83: 7470 | G83: 0.172 | H83: 16 | I83: 83.5 | J83: 2.29 | K83: 0 | L83: 3.3 | M83: 776922.17 | N83: 150701.93
A84: STR-1020 | B84: 45748 | C84: South | D84: High Street | E84: 77999.9 | F84: 5974 | G84: 0.252 | H84: 14 | I84: 81.3 | J84: 2.39 | K84: 0 | L84: 3.2 | M84: 636561.34 | N84: 93861.06
A85: STR-1021 | B85: 45658 | C85: West | D85: Mall | E85: 60881.01 | F85: 5410 | G85: 0.179 | H85: 15 | I85: 83.9 | J85: 5.24 | K85: 0 | L85: 4.6 | M85: 621369.58 | N85: 85493.64
...

Sheet Cleaned_Data
A1: Cleaned / Prepared Data
A2: Missing competitor_distance_km (6 rows) and customer_rating (8 rows) imputed with the column median. All other columns are unchanged from Original_Data. Flag columns mark imputed cells.
A4: store_id | B4: month | C4: region | D4: store_type | E4: marketing_spend | F4: footfall | G4: avg_discount_pct | H4: staff_count | I4: inventory_availability_pct | J4: competitor_distance_km | K4: competitor_distance_km_imputed | L4: holiday_flag | M4: customer_rating | N4: customer_rating_imputed | O4: monthly_sales | P4: monthly_profit
A5: STR-1001 | B5: 45658 | C5: East | D5: Residential | E5: 70389.11 | F5: 8302 | G5: 0.042 | H5: 17 | I5: 75 | J5: 5.28 | K5: No | L5: 1 | M5: 3.1 | N5: No | O5: 658832.62 | P5: 84349.93
A6: STR-1001 | B6: 45689 | C6: East | D6: Residential | E6: 43827.89 | F6: 8487 | G6: 0.168 | H6: 23 | I6: 84.4 | J6: 4.31 | K6: No | L6: 0 | M6: 2.8 | N6: No | O6: 634436 | P6: 106130.54
A7: STR-1001 | B7: 45717 | C7: East | D7: Residential | E7: 59921.75 | F7: 9113 | G7: 0.133 | H7: 20 | I7: 88 | J7: 12 | K7: No | L7: 0 | M7: 3.2 | N7: No | O7: 678722.06 | P7: 101883.86
A8: STR-1001 | B8: 45748 | C8: East | D8: Residential | E8: 56856.63 | F8: 9431 | G8: 0.142 | H8: 23 | I8: 86.9 | J8: 4.97 | K8: No | L8: 0 | M8: 3.4 | N8: No | O8: 658920.3 | P8: 97910.37
A9: STR-1002 | B9: 45658 | C9: East | D9: High Street | E9: 48412.64 | F9: 9545 | G9: 0.231 | H9: 21 | I9: 97.6 | J9: 6.94 | K9: No | L9: 1 | M9: 4.2 | N9: No | O9: 741341.44 | P9: 119208.17
A10: STR-1002 | B10: 45689 | C10: East | D10: High Street | E10: 64811.21 | F10: 9792 | G10: 0.112 | H10: 20 | I10: 84.2 | J10: 2.88 | K10: No | L10: 0 | M10: 4.2 | N10: No | O10: 761835.34 | P10: 149602.23
A11: STR-1002 | B11: 45717 | C11: East | D11: High Street | E11: 46213.45 | F11: 10616 | G11: 0.122 | H11: 22 | I11: 85.2 | J11: 0.2 | K11: No | L11: 1 | M11: 4.1 | N11: No | O11: 806615.54 | P11: 131364.62
A12: STR-1002 | B12: 45748 | C12: East | D12: High Street | E12: 68148.52 | F12: 8567 | G12: 0.127 | H12: 23 | I12: 95.6 | J12: 0.8 | K12: No | L12: 0 | M12: 3.9 | N12: No | O12: 850164.26 | P12: 149262.75
A13: STR-1003 | B13: 45658 | C13: North | D13: Airport | E13: 71838.86 | F13: 10979 | G13: 0.215 | H13: 26 | I13: 88.6 | J13: 7.7 | K13: No | L13: 1 | M13: 3.8 | N13: No | O13: 930581.7 | P13: 136207.98
A14: STR-1003 | B14: 45689 | C14: North | D14: Airport | E14: 68133.44 | F14: 9459 | G14: 0.22 | H14: 21 | I14: 85 | J14: 1.91 | K14: No | L14: 0 | M14: 4.2 | N14: No | O14: 779010.94 | P14: 106328.09
A15: STR-1003 | B15: 45717 | C15: North | D15: Airport | E15: 34285.21 | F15: 9172 | G15: 0.213 | H15: 22 | I15: 88.3 | J15: 10.46 | K15: No | L15: 1 | M15: 3.8 | N15: No | O15: 723060.76 | P15: 123131.24
A16: STR-1003 | B16: 45748 | C16: North | D16: Airport | E16: 67979.88 | F16: 11230 | G16: 0.002 | H16: 28 | I16: 85.3 | J16: 7.16 | K16: No | L16: 0 | M16: 3.8 | N16: No | O16: 910791.94 | P16: 158891.28
... A324: STR-1080 | B324: 45748 | C324: East | D324: Residential | E324: 40553.11 | F324: 5317 | G324: 0.165 | H324: 17 | I324: 84.3 | J324: 11.82 | K324: No | L324: 0 | M324: 4.1 | N324: No | O324: 559660.84 | P324: 71443.61

Sheet Dummy_Variables
A1: Dummy Variable Creation — Regression-Ready Table
A2: store_type (Mall, High Street, Residential, Airport) is converted into 3 dummy columns. Reference category = "High Street" (most common type, n=116) — it is intentionally left out to avoid the dummy-variable trap (perfect multicollinearity if all 4 categories + an intercept were included together). Each dummy coefficient in the regression is read as the sales difference vs. a High Street store, all else equal.
A4: store_id | B4: month | C4: region | D4: store_type | E4: marketing_spend | F4: footfall | G4: avg_discount_pct | H4: inventory_availability_pct | I4: competitor_distance_km | J4: holiday_flag | K4: customer_rating | L4: store_type_Mall | M4: store_type_Residential | N4: store_type_Airport | O4: staff_count | P4: monthly_sales | Q4: monthly_profit
A5: STR-1001 | B5: 45658 | C5: East | D5: Residential | E5: 70389.11 | F5: 8302 | G5: 0.042 | H5: 75 | I5: 5.28 | J5: 1 | K5: 3.1 | L5: 0 | M5: 1 | N5: 0 | O5: 17 | P5: 658832.62 | Q5: 84349.93
A6: STR-1001 | B6: 45689 | C6: East | D6: Residential | E6: 43827.89 | F6: 8487 | G6: 0.168 | H6: 84.4 | I6: 4.31 | J6: 0 | K6: 2.8 | L6: 0 | M6: 1 | N6: 0 | O6: 23 | P6: 634436 | Q6: 106130.54
A7: STR-1001 | B7: 45717 | C7: East | D7: Residential | E7: 59921.75 | F7: 9113 | G7: 0.133 | H7: 88 | I7: 12 | J7: 0 | K7: 3.2 | L7: 0 | M7: 1 | N7: 0 | O7: 20 | P7: 678722.06 | Q7: 101883.86
A8: STR-1001 | B8: 45748 | C8: East | D8: Residential | E8: 56856.63 | F8: 9431 | G8: 0.142 | H8: 86.9 | I8: 4.97 | J8: 0 | K8: 3.4 | L8: 0 | M8: 1 | N8: 0 | O8: 23 | P8: 658920.3 | Q8: 97910.37
A9: STR-1002 | B9: 45658 | C9: East | D9: High Street | E9: 48412.64 | F9: 9545 | G9: 0.231 | H9: 97.6 | I9: 6.94 | J9: 1 | K9: 4.2 | L9: 0 | M9: 0 | N9: 0 | O9: 21 | P9: 741341.44 | Q9: 119208.17
A10: STR-1002 | B10: 45689 | C10: East | D10: High Street | E10: 64811.21 | F10: 9792 | G10: 0.112 | H10: 84.2 | I10: 2.88 | J10: 0 | K10: 4.2 | L10: 0 | M10: 0 | N10: 0 | O10: 20 | P10: 761835.34 | Q10: 149602.23
A11: STR-1002 | B11: 45717 | C11: East | D11: High Street | E11: 46213.45 | F11: 10616 | G11: 0.122 | H11: 85.2 | I11: 0.2 | J11: 1 | K11: 4.1 | L11: 0 | M11: 0 | N11: 0 | O11: 22 | P11: 806615.54 | Q11: 131364.62
A12: STR-1002 | B12: 45748 | C12: East | D12: High Street | E12: 68148.52 | F12: 8567 | G12: 0.127 | H12: 95.6 | I12: 0.8 | J12: 0 | K12: 3.9 | L12: 0 | M12: 0 | N12: 0 | O12: 23 | P12: 850164.26 | Q12: 149262.75
A13: STR-1003 | B13: 45658 | C13: North | D13: Airport | E13: 71838.86 | F13: 10979 | G13: 0.215 | H13: 88.6 | I13: 7.7 | J13: 1 | K13: 3.8 | L13: 0 | M13: 0 | N13: 1 | O13: 26 | P13: 930581.7 | Q13: 136207.98
A14: STR-1003 | B14: 45689 | C14: North | D14: Airport | E14: 68133.44 | F14: 9459 | G14: 0.22 | H14: 85 | I14: 1.91 | J14: 0 | K14: 4.2 | L14: 0 | M14: 0 | N14: 1 | O14: 21 | P14: 779010.94 | Q14: 106328.09
A15: STR-1003 | B15: 45717 | C15: North | D15: Airport | E15: 34285.21 | F15: 9172 | G15: 0.213 | H15: 88.3 | I15: 10.46 | J15: 1 | K15: 3.8 | L15: 0 | M15: 0 | N15: 1 | O15: 22 | P15: 723060.76 | Q15: 123131.24
A16: STR-1003 | B16: 45748 | C16: North | D16: Airport | E16: 67979.88 | F16: 11230 | G16: 0.002 | H16: 85.3 | I16: 7.16 | J16: 0 | K16: 3.8 | L16: 0 | M16: 0 | N16: 1 | O16: 28 | P16: 910791.94 | Q16: 158891.28
... A324: STR-1080 | B324: 45748 | C324: East | D324: Residential | E324: 40553.11 | F324: 5317 | G324: 0.165 | H324: 84.3 | I324: 11.82 | J324: 0 | K324: 4.1 | L324: 0 | M324: 1 | N324: 0 | O324: 17 | P324: 559660.84 | Q324: 71443.61

Sheet Simple_Regression
A1: Simple Linear Regression Models
A2: Each model regresses monthly_sales on a single independent variable. Computed live via Excel LINEST().
A4: Simple Model 1: monthly_sales ~ marketing_spend
A5: {=LINEST(Dummy_Variables!$P$5:$P$324,Dummy_Variables!$E$5:$E$324,TRUE(),TRUE())} -> 2.1295753 | B5: 560777.35 | D5: Row 1: [slope, intercept]
A6: 0.26647838 | B6: 15906.906 | D6: Row 2: [SE(slope), SE(intercept)]
A7: 0.16724469 | B7: 94846.034 | D7: Row 3: [R-squared, SE(y)]
A8: 63.864873 | B8: 318 | D8: Row 4: [F-statistic, df residual]
A9: 5.7451371e+11 | B9: 2.8606549e+12 | D9: Row 5: [SS regression, SS residual]
A11: Statistic | B11: Value
A12: Slope (coefficient) | B12: =A5 -> 2.1295753
A13: Intercept | B13: =B5 -> 560777.35
A14: R-squared | B14: =A7 -> 0.16724469
A15: Standard Error of slope | B15: =A6 -> 0.26647838
A16: t-statistic | B16: =A5/A6 -> 7.9915501
A17: Degrees of freedom (resid.) | B17: =B8 -> 318
A18: P-value (two-tailed) | B18: =_xlfn.T.DIST.2T(ABS(A5/A6),B8) -> 2.4800615e-14
A19: N (observations) | B19: 320
A20: Equation | B20: ="monthly_sales = "&TEXT(B5,"#,##0.00")&" + ("&TEXT(A5,"#,##0.0000")&" x marketing_spend)" -> monthly_sales = 560,777.35 + (2.1296 x marketing_spend)
A23: Simple Model 2: monthly_sales ~ footfall
A24: {=LINEST(Dummy_Variables!$P$5:$P$324,Dummy_Variables!$F$5:$F$324,TRUE(),TRUE())} -> 35.678031 | B24: 446410.58 | D24: Row 1: [slope, intercept]
A25: 1.1973783 | B25: 8407.7383 | D25: Row 2: [SE(slope), SE(intercept)]
A26: 0.73628534 | B26: 53373.736 | D26: Row 3: [R-squared, SE(y)]
A27: 887.84878 | B27: 318 | D27: Row 4: [F-statistic, df residual]
A28: 2.5292643e+12 | B28: 9.0590432e+11 | D28: Row 5: [SS regression, SS residual]
A30: Statistic | B30: Value
A31: Slope (coefficient) | B31: =A24 -> 35.678031
A32: Intercept | B32: =B24 -> 446410.58
A33: R-squared | B33: =A26 -> 0.73628534
A34: Standard Error of slope | B34: =A25 -> 1.1973783
A35: t-statistic | B35: =A24/A25 -> 29.796791
A36: Degrees of freedom (resid.) | B36: =B27 -> 318
A37: P-value (two-tailed) | B37: =_xlfn.T.DIST.2T(ABS(A24/A25),B27) -> 4.7503615e-94
A38: N (observations) | B38: 320
A39: Equation | B39: ="monthly_sales = "&TEXT(B24,"#,##0.00")&" + ("&TEXT(A24,"#,##0.0000")&" x footfall)" -> monthly_sales = 446,410.58 + (35.6780 x footfall)
A42: Simple Model 3: monthly_sales ~ avg_discount_pct
A43: {=LINEST(Dummy_Variables!$P$5:$P$324,Dummy_Variables!$G$5:$G$324,TRUE(),TRUE())} -> -138730.45 | B43: 697835.63 | D43: Row 1: [slope, intercept]
A44: 85086.38 | B44: 12035.419 | D44: Row 2: [SE(slope), SE(intercept)]
A45: 0.008290503 | B45: 103502.94 | D45: Row 3: [R-squared, SE(y)]
A46: 2.6584196 | B46: 318 | D46: Row 4: [F-statistic, df residual]
A47: 2.8479276e+10 | B47: 3.4066893e+12 | D47: Row 5: [SS regression, SS residual]
...

Sheet Multiple_Regression
A1: Multiple Linear Regression Models
A2: Model A includes all numeric predictors + staff_count + store_type dummies. Model B (FINAL MODEL) drops staff_count because it is highly correlated with footfall (r = 0.92), which destabilizes both coefficients without meaningfully improving R-squared. See model_comparison.md for the full justification.
A4: Model A — Full Multiple Regression (includes staff_count)
A5: X variables (11): marketing_spend, footfall, avg_discount_pct, inventory_availability_pct, competitor_distance_km, holiday_flag, customer_rating, store_type_Mall, store_type_Residential, store_type_Airport, staff_count
A6: {=LINEST(Dummy_Variables!$P$5:$P$324,Dummy_Variables!$E$5:$O$324,TRUE(),TRUE())} -> 3356.6538 | B6: 23372.265 | C6: -20025.15 | D6: 11636.327 | E6: 12786.75 | F6: 12921.273 | G6: -3113.4835 | H6: 3166.2349 | I6: -58513.543 | J6: 27.438989 | K6: 1.1894992 | L6: 69085.084 | N6: Row 1: coefficients (reverse x-order), intercept last
A7: 1192.3924 | B7: 8782.0604 | C7: 5713.9765 | D7: 6153.5684 | E7: 4543.5644 | F7: 6278.4081 | G7: 547.82849 | H7: 436.68773 | I7: 34343.582 | J7: 2.3622212 | K7: 0.12025026 | L7: 45910.174 | N7: Row 2: standard errors (same order)
A8: 0.84699062 | B8: 41310.238 | C8: #N/A | D8: #N/A | E8: #N/A | F8: #N/A | G8: #N/A | H8: #N/A | I8: #N/A | J8: #N/A | K8: #N/A | L8: #N/A | N8: Row 3: [R-squared, SE(y)]
A9: 154.99531 | B9: 308 | C9: #N/A | D9: #N/A | E9: #N/A | F9: #N/A | G9: #N/A | H9: #N/A | I9: #N/A | J9: #N/A | K9: #N/A | L9: #N/A | N9: Row 4: [F-statistic, df residual] | O9: Note: #N/A in rows 4-5 beyond column B is standard Excel LINEST behavior (F-stat/df/SS only ever occupy the first 2 columns) — not a formula error.
A10: 2.9095556e+12 | B10: 5.2561303e+11 | C10: #N/A | D10: #N/A | E10: #N/A | F10: #N/A | G10: #N/A | H10: #N/A | I10: #N/A | J10: #N/A | K10: #N/A | L10: #N/A | N10: Row 5: [SS regression, SS residual]
A12: Coefficient Table
A13: Variable | B13: Coefficient | C13: Std. Error | D13: t-stat | E13: P-value | F13: 95% Sig.?
A14: Intercept | B14: =L6 -> 69085.084 | C14: =L7 -> 45910.174 | D14: =B14/C14 -> 1.5047881 | E14: =_xlfn.T.DIST.2T(ABS(D14),B9) -> 0.13340332 | F14: =IF(E14<0.05,"Yes","No") -> No
A15: marketing_spend | B15: =K6 -> 1.1894992 | C15: =K7 -> 0.12025026 | D15: =B15/C15 -> 9.8918638 | E15: =_xlfn.T.DIST.2T(ABS(D15),B9) -> 3.2403942e-20 | F15: =IF(E15<0.05,"Yes","No") -> Yes
A16: footfall | B16: =J6 -> 27.438989 | C16: =J7 -> 2.3622212 | D16: =B16/C16 -> 11.615758 | E16: =_xlfn.T.DIST.2T(ABS(D16),B9) -> 4.1126792e-26 | F16: =IF(E16<0.05,"Yes","No") -> Yes
A17: avg_discount_pct | B17: =I6 -> -58513.543 | C17: =I7 -> 34343.582 | D17: =B17/C17 -> -1.7037694 | E17: =_xlfn.T.DIST.2T(ABS(D17),B9) -> 0.089432804 | F17: =IF(E17<0.05,"Yes","No") -> No
A18: inventory_availability_pct | B18: =H6 -> 3166.2349 | C18: =H7 -> 436.68773 | D18: =B18/C18 -> 7.2505698 | E18: =_xlfn.T.DIST.2T(ABS(D18),B9) -> 3.3717327e-12 | F18: =IF(E18<0.05,"Yes","No") -> Yes
A19: competitor_distance_km | B19: =G6 -> -3113.4835 | C19: =G7 -> 547.82849 | D19: =B19/C19 -> -5.683318 | E19: =_xlfn.T.DIST.2T(ABS(D19),B9) -> 3.0635519e-08 | F19: =IF(E19<0.05,"Yes","No") -> Yes
A20: holiday_flag | B20: =F6 -> 12921.273 | C20: =F7 -> 6278.4081 | D20: =B20/C20 -> 2.0580493 | E20: =_xlfn.T.DIST.2T(ABS(D20),B9) -> 0.040426555 | F20: =IF(E20<0.05,"Yes","No") -> Yes
A21: customer_rating | B21: =E6 -> 12786.75 | C21: =E7 -> 4543.5644 | D21: =B21/C21 -> 2.8142553 | E21: =_xlfn.T.DIST.2T(ABS(D21),B9) -> 0.0052036778 | F21: =IF(E21<0.05,"Yes","No") -> Yes
A22: store_type_Mall | B22: =D6 -> 11636.327 | C22: =D7 -> 6153.5684 | D22: =B22/C22 -> 1.8909885 | E22: =_xlfn.T.DIST.2T(ABS(D22),B9) -> 0.059564183 | F22: =IF(E22<0.05,"Yes","No") -> No
A23: store_type_Residential | B23: =C6 -> -20025.15 | C23: =C7 -> 5713.9765 | D23: =B23/C23 -> -3.5045908 | E23: =_xlfn.T.DIST.2T(ABS(D23),B9) -> 0.00052516535 | F23: =IF(E23<0.05,"Yes","No") -> Yes
A24: store_type_Airport | B24: =B6 -> 23372.265 | C24: =B7 -> 8782.0604 | D24: =B24/C24 -> 2.6613646 | E24: =_xlfn.T.DIST.2T(ABS(D24),B9) -> 0.0081906293 | F24: =IF(E24<0.05,"Yes","No") -> Yes
A25: staff_count | B25: =A6 -> 3356.6538 | C25: =A7 -> 1192.3924 | D25: =B25/C25 -> 2.8150581 | E25: =_xlfn.T.DIST.2T(ABS(D25),B9) -> 0.0051910277 | F25: =IF(E25<0.05,"Yes","No") -> Yes
A27: R-squared | B27: =A8 -> 0.84699062
A28: Adjusted R-squared | B28: =1-(1-A8)*(320-1)/(320-11-1) -> 0.841526
A29: F-statistic | B29: =A9 -> 154.99531
A30: N predictors | B30: 11
A31: N observations | B31: 320
A34: Model B — FINAL Multiple Regression (drops staff_count; multicollinearity fix)
A35: X variables (10): marketing_spend, footfall, avg_discount_pct, inventory_availability_pct, competitor_distance_km, holiday_flag, customer_rating, store_type_Mall, store_type_Residential, store_type_Airport
A36: {=LINEST(Dummy_Variables!$P$5:$P$324,Dummy_Variables!$E$5:$N$324,TRUE(),TRUE())} -> 24123.17 | B36: -18844.933 | C36: 11948.283 | D36: 12309.477 | E36: 12000.525 | F36: -3039.486 | G36: 3117.0904 | H36: -53647.682 | I36: 33.494548 | J36: 1.2074729 | K36: 88595.773 | M36: Row 1: coefficients (reverse x-order), intercept last
A37: 8875.819 | B37: 5762.0724 | C37: 6221.1267 | D37: 4590.9924 | E37: 6339.7459 | F37: 553.29474 | G37: 441.20062 | H37: 34682.252 | I37: 0.98695235 | J37: 0.12141866 | K37: 45889.702 | M37: Row 2: standard errors (same order)
A38: 0.84305383 | B38: 41770.546 | C38: #N/A | D38: #N/A | E38: #N/A | F38: #N/A | G38: #N/A | H38: #N/A | I38: #N/A | J38: #N/A | K38: #N/A | M38: Row 3: [R-squared, SE(y)]
A39: 165.98279 | B39: 309 | C39: #N/A | D39: #N/A | E39: #N/A | F39: #N/A | G39: #N/A | H39: #N/A | I39: #N/A | J39: #N/A | K39: #N/A | M39: Row 4: [F-statistic, df residual] | N39: Note: #N/A in rows 4-5 beyond column B is standard Excel LINEST behavior (F-stat/df/SS only ever occupy the first 2 columns) — not a formula error.
A40: 2.8960321e+12 | B40: 5.3913656e+11 | C40: #N/A | D40: #N/A | E40: #N/A | F40: #N/A | G40: #N/A | H40: #N/A | I40: #N/A | J40: #N/A | K40: #N/A | M40: Row 5: [SS regression, SS residual]
A42: Coefficient Table
A43: Variable | B43: Coefficient | C43: Std. Error | D43: t-stat | E43: P-value | F43: 95% Sig.?
A44: Intercept | B44: =K36 -> 88595.773 | C44: =K37 -> 45889.702 | D44: =B44/C44 -> 1.9306243 | E44: =_xlfn.T.DIST.2T(ABS(D44),B39) -> 0.054444287 | F44: =IF(E44<0.05,"Yes","No") -> No
A45: marketing_spend | B45: =J36 -> 1.2074729 | C45: =J37 -> 0.12141866 | D45: =B45/C45 -> 9.9447061 | E45: =_xlfn.T.DIST.2T(ABS(D45),B39) -> 2.1307626e-20 | F45: =IF(E45<0.05,"Yes","No") -> Yes
A46: footfall | B46: =I36 -> 33.494548 | C46: =I37 -> 0.98695235 | D46: =B46/C46 -> 33.93735 | E46: =_xlfn.T.DIST.2T(ABS(D46),B39) -> 3.0181543e-106 | F46: =IF(E46<0.05,"Yes","No") -> Yes
...

Sheet Predictions_Residuals
A1: Predicted Sales & Residuals — FINAL Model (Model B)
A2: predicted_sales uses the Model B coefficients from Multiple_Regression (cells B44:B54). residual = monthly_sales - predicted_sales.
A4: store_id | B4: month | C4: region | D4: store_type | E4: monthly_sales | F4: predicted_sales | G4: residual | H4: abs_residual
A5: =Dummy_Variables!A5 -> STR-1001 | B5: =Dummy_Variables!B5 -> 45658 | C5: =Dummy_Variables!C5 -> East | D5: =Dummy_Variables!D5 -> Residential | E5: =Dummy_Variables!P5 -> 658832.62 | F5: =Multiple_Regression!$B$44+Multiple_Regression!$B$45*Dummy_Variables!E5+Multiple_Regression!$B$46*Dummy_Variables!F5+Multiple_Regression!$B$47*Dummy_Variables!G5+Multiple_Regression!$B$48*Dummy_Variables!H5+Multiple_Regression!$B$49*Dummy_Variables!I5+Multiple_Regression!$B$50*Dummy_Variables!J5+Multiple_Regression!$B$51*Dummy_Variables!K5+Multiple_Regression!$B$52*Dummy_Variables!L5+Multiple_Regression!$B$53*Dummy_Variables!M5+Multiple_Regression!$B$54*Dummy_Variables!N5 -> 698455.51 | G5: =E5-F5 -> -39622.895 | H5: =ABS(G5) -> 39622.895
A6: =Dummy_Variables!A6 -> STR-1001 | B6: =Dummy_Variables!B6 -> 45689 | C6: =Dummy_Variables!C6 -> East | D6: =Dummy_Variables!D6 -> Residential | E6: =Dummy_Variables!P6 -> 634436 | F6: =Multiple_Regression!$B$44+Multiple_Regression!$B$45*Dummy_Variables!E6+Multiple_Regression!$B$46*Dummy_Variables!F6+Multiple_Regression!$B$47*Dummy_Variables!G6+Multiple_Regression!$B$48*Dummy_Variables!H6+Multiple_Regression!$B$49*Dummy_Variables!I6+Multiple_Regression!$B$50*Dummy_Variables!J6+Multiple_Regression!$B$51*Dummy_Variables!K6+Multiple_Regression!$B$52*Dummy_Variables!L6+Multiple_Regression!$B$53*Dummy_Variables!M6+Multiple_Regression!$B$54*Dummy_Variables!N6 -> 682376.03 | G6: =E6-F6 -> -47940.028 | H6: =ABS(G6) -> 47940.028
A7: =Dummy_Variables!A7 -> STR-1001 | B7: =Dummy_Variables!B7 -> 45717 | C7: =Dummy_Variables!C7 -> East | D7: =Dummy_Variables!D7 -> Residential | E7: =Dummy_Variables!P7 -> 678722.06 | F7: =Multiple_Regression!$B$44+Multiple_Regression!$B$45*Dummy_Variables!E7+Multiple_Regression!$B$46*Dummy_Variables!F7+Multiple_Regression!$B$47*Dummy_Variables!G7+Multiple_Regression!$B$48*Dummy_Variables!H7+Multiple_Regression!$B$49*Dummy_Variables!I7+Multiple_Regression!$B$50*Dummy_Variables!J7+Multiple_Regression!$B$51*Dummy_Variables!K7+Multiple_Regression!$B$52*Dummy_Variables!L7+Multiple_Regression!$B$53*Dummy_Variables!M7+Multiple_Regression!$B$54*Dummy_Variables!N7 -> 717425.85 | G7: =E7-F7 -> -38703.793 | H7: =ABS(G7) -> 38703.793
A8: =Dummy_Variables!A8 -> STR-1001 | B8: =Dummy_Variables!B8 -> 45748 | C8: =Dummy_Variables!C8 -> East | D8: =Dummy_Variables!D8 -> Residential | E8: =Dummy_Variables!P8 -> 658920.3 | F8: =Multiple_Regression!$B$44+Multiple_Regression!$B$45*Dummy_Variables!E8+Multiple_Regression!$B$46*Dummy_Variables!F8+Multiple_Regression!$B$47*Dummy_Variables!G8+Multiple_Regression!$B$48*Dummy_Variables!H8+Multiple_Regression!$B$49*Dummy_Variables!I8+Multiple_Regression!$B$50*Dummy_Variables!J8+Multiple_Regression!$B$51*Dummy_Variables!K8+Multiple_Regression!$B$52*Dummy_Variables!L8+Multiple_Regression!$B$53*Dummy_Variables!M8+Multiple_Regression!$B$54*Dummy_Variables!N8 -> 744293.92 | G8: =E8-F8 -> -85373.623 | H8: =ABS(G8) -> 85373.623
A9: =Dummy_Variables!A9 -> STR-1002 | B9: =Dummy_Variables!B9 -> 45658 | C9: =Dummy_Variables!C9 -> East | D9: =Dummy_Variables!D9 -> High Street | E9: =Dummy_Variables!P9 -> 741341.44 | F9: =Multiple_Regression!$B$44+Multiple_Regression!$B$45*Dummy_Variables!E9+Multiple_Regression!$B$46*Dummy_Variables!F9+Multiple_Regression!$B$47*Dummy_Variables!G9+Multiple_Regression!$B$48*Dummy_Variables!H9+Multiple_Regression!$B$49*Dummy_Variables!I9+Multiple_Regression!$B$50*Dummy_Variables!J9+Multiple_Regression!$B$51*Dummy_Variables!K9+Multiple_Regression!$B$52*Dummy_Variables!L9+Multiple_Regression!$B$53*Dummy_Variables!M9+Multiple_Regression!$B$54*Dummy_Variables!N9 -> 801199.89 | G9: =E9-F9 -> -59858.448 | H9: =ABS(G9) -> 59858.448
A10: =Dummy_Variables!A10 -> STR-1002 | B10: =Dummy_Variables!B10 -> 45689 | C10: =Dummy_Variables!C10 -> East | D10: =Dummy_Variables!D10 -> High Street | E10: =Dummy_Variables!P10 -> 761835.34 | F10: =Multiple_Regression!$B$44+Multiple_Regression!$B$45*Dummy_Variables!E10+Multiple_Regression!$B$46*Dummy_Variables!F10+Multiple_Regression!$B$47*Dummy_Variables!G10+Multiple_Regression!$B$48*Dummy_Variables!H10+Multiple_Regression!$B$49*Dummy_Variables!I10+Multiple_Regression!$B$50*Dummy_Variables!J10+Multiple_Regression!$B$51*Dummy_Variables!K10+Multiple_Regression!$B$52*Dummy_Variables!L10+Multiple_Regression!$B$53*Dummy_Variables!M10+Multiple_Regression!$B$54*Dummy_Variables!N10 -> 794228.72 | G10: =E10-F10 -> -32393.381 | H10: =ABS(G10) -> 32393.381
A11: =Dummy_Variables!A11 -> STR-1002 | B11: =Dummy_Variables!B11 -> 45717 | C11: =Dummy_Variables!C11 -> East | D11: =Dummy_Variables!D11 -> High Street | E11: =Dummy_Variables!P11 -> 806615.54 | F11: =Multiple_Regression!$B$44+Multiple_Regression!$B$45*Dummy_Variables!E11+Multiple_Regression!$B$46*Dummy_Variables!F11+Multiple_Regression!$B$47*Dummy_Variables!G11+Multiple_Regression!$B$48*Dummy_Variables!H11+Multiple_Regression!$B$49*Dummy_Variables!I11+Multiple_Regression!$B$50*Dummy_Variables!J11+Multiple_Regression!$B$51*Dummy_Variables!K11+Multiple_Regression!$B$52*Dummy_Variables!L11+Multiple_Regression!$B$53*Dummy_Variables!M11+Multiple_Regression!$B$54*Dummy_Variables!N11 -> 820867.95 | G11: =E11-F11 -> -14252.41 | H11: =ABS(G11) -> 14252.41
A12: =Dummy_Variables!A12 -> STR-1002 | B12: =Dummy_Variables!B12 -> 45748 | C12: =Dummy_Variables!C12 -> East | D12: =Dummy_Variables!D12 -> High Street | E12: =Dummy_Variables!P12 -> 850164.26 | F12: =Multiple_Regression!$B$44+Multiple_Regression!$B$45*Dummy_Variables!E12+Multiple_Regression!$B$46*Dummy_Variables!F12+Multiple_Regression!$B$47*Dummy_Variables!G12+Multiple_Regression!$B$48*Dummy_Variables!H12+Multiple_Regression!$B$49*Dummy_Variables!I12+Multiple_Regression!$B$50*Dummy_Variables!J12+Multiple_Regression!$B$51*Dummy_Variables!K12+Multiple_Regression!$B$52*Dummy_Variables!L12+Multiple_Regression!$B$53*Dummy_Variables!M12+Multiple_Regression!$B$54*Dummy_Variables!N12 -> 794587.01 | G12: =E12-F12 -> 55577.245 | H12: =ABS(G12) -> 55577.245
A13: =Dummy_Variables!A13 -> STR-1003 | B13: =Dummy_Variables!B13 -> 45658 | C13: =Dummy_Variables!C13 -> North | D13: =Dummy_Variables!D13 -> Airport | E13: =Dummy_Variables!P13 -> 930581.7 | F13: =Multiple_Regression!$B$44+Multiple_Regression!$B$45*Dummy_Variables!E13+Multiple_Regression!$B$46*Dummy_Variables!F13+Multiple_Regression!$B$47*Dummy_Variables!G13+Multiple_Regression!$B$48*Dummy_Variables!H13+Multiple_Regression!$B$49*Dummy_Variables!I13+Multiple_Regression!$B$50*Dummy_Variables!J13+Multiple_Regression!$B$51*Dummy_Variables!K13+Multiple_Regression!$B$52*Dummy_Variables!L13+Multiple_Regression!$B$53*Dummy_Variables!M13+Multiple_Regression!$B$54*Dummy_Variables!N13 -> 867211.51 | G13: =E13-F13 -> 63370.186 | H13: =ABS(G13) -> 63370.186
A14: =Dummy_Variables!A14 -> STR-1003 | B14: =Dummy_Variables!B14 -> 45689 | C14: =Dummy_Variables!C14 -> North | D14: =Dummy_Variables!D14 -> Airport | E14: =Dummy_Variables!P14 -> 779010.94 | F14: =Multiple_Regression!$B$44+Multiple_Regression!$B$45*Dummy_Variables!E14+Multiple_Regression!$B$46*Dummy_Variables!F14+Multiple_Regression!$B$47*Dummy_Variables!G14+Multiple_Regression!$B$48*Dummy_Variables!H14+Multiple_Regression!$B$49*Dummy_Variables!I14+Multiple_Regression!$B$50*Dummy_Variables!J14+Multiple_Regression!$B$51*Dummy_Variables!K14+Multiple_Regression!$B$52*Dummy_Variables!L14+Multiple_Regression!$B$53*Dummy_Variables!M14+Multiple_Regression!$B$54*Dummy_Variables!N14 -> 810857.73 | G14: =E14-F14 -> -31846.793 | H14: =ABS(G14) -> 31846.793
A15: =Dummy_Variables!A15 -> STR-1003 | B15: =Dummy_Variables!B15 -> 45717 | C15: =Dummy_Variables!C15 -> North | D15: =Dummy_Variables!D15 -> Airport | E15: =Dummy_Variables!P15 -> 723060.76 | F15: =Multiple_Regression!$B$44+Multiple_Regression!$B$45*Dummy_Variables!E15+Multiple_Regression!$B$46*Dummy_Variables!F15+Multiple_Regression!$B$47*Dummy_Variables!G15+Multiple_Regression!$B$48*Dummy_Variables!H15+Multiple_Regression!$B$49*Dummy_Variables!I15+Multiple_Regression!$B$50*Dummy_Variables!J15+Multiple_Regression!$B$51*Dummy_Variables!K15+Multiple_Regression!$B$52*Dummy_Variables!L15+Multiple_Regression!$B$53*Dummy_Variables!M15+Multiple_Regression!$B$54*Dummy_Variables!N15 -> 752125.04 | G15: =E15-F15 -> -29064.279 | H15: =ABS(G15) -> 29064.279
A16: =Dummy_Variables!A16 -> STR-1003 | B16: =Dummy_Variables!B16 -> 45748 | C16: =Dummy_Variables!C16 -> North | D16: =Dummy_Variables!D16 -> Airport | E16: =Dummy_Variables!P16 -> 910791.94 | F16: =Multiple_Regression!$B$44+Multiple_Regression!$B$45*Dummy_Variables!E16+Multiple_Regression!$B$46*Dummy_Variables!F16+Multiple_Regression!$B$47*Dummy_Variables!G16+Multiple_Regression!$B$48*Dummy_Variables!H16+Multiple_Regression!$B$49*Dummy_Variables!I16+Multiple_Regression!$B$50*Dummy_Variables!J16+Multiple_Regression!$B$51*Dummy_Variables!K16+Multiple_Regression!$B$52*Dummy_Variables!L16+Multiple_Regression!$B$53*Dummy_Variables!M16+Multiple_Regression!$B$54*Dummy_Variables!N16 -> 861740.39 | G16: =E16-F16 -> 49051.553 | H16: =ABS(G16) -> 49051.553
... A324: =Dummy_Variables!A324 -> STR-1080 | B324: =Dummy_Variables!B324 -> 45748 | C324: =Dummy_Variables!C324 -> East | D324: =Dummy_Variables!D324 -> Residential | E324: =Dummy_Variables!P324 -> 559660.84 | F324: =Multiple_Regression!$B$44+Multiple_Regression!$B$45*Dummy_Variables!E324+Multiple_Regression!$B$46*Dummy_Variables!F324+Multiple_Regression!$B$47*Dummy_Variables!G324+Multiple_Regression!$B$48*Dummy_Variables!H324+Multiple_Regression!$B$49*Dummy_Variables!I324+Multiple_Regression!$B$50*Dummy_Variables!J324+Multiple_Regression!$B$51*Dummy_Variables!K324+Multiple_Regression!$B$52*Dummy_Variables!L324+Multiple_Regression!$B$53*Dummy_Variables!M324+Multiple_Regression!$B$54*Dummy_Variables!N324 -> 565269.12 | G324: =E324-F324 -> -5608.279 | H324: =ABS(G324) -> 5608.279
A327: Top 5 Largest POSITIVE Residuals (model under-predicts — actual sales exceed prediction)
A328: Rank | B328: store_id | C328: month | D328: store_type | E328: region | F328: monthly_sales | G328: predicted_sales | H328: residual
A329: 1 | B329: =INDEX($A$5:$A$324,MATCH(LARGE($G$5:$G$324,1),$G$5:$G$324,0)) -> STR-1058 | C329: =INDEX($B$5:$B$324,MATCH(LARGE($G$5:$G$324,1),$G$5:$G$324,0)) -> 45689 | D329: =INDEX($D$5:$D$324,MATCH(LARGE($G$5:$G$324,1),$G$5:$G$324,0)) -> High Street | E329: =INDEX($C$5:$C$324,MATCH(LARGE($G$5:$G$324,1),$G$5:$G$324,0)) -> East | F329: =INDEX($E$5:$E$324,MATCH(LARGE($G$5:$G$324,1),$G$5:$G$324,0)) -> 870937.4 | G329: =INDEX($F$5:$F$324,MATCH(LARGE($G$5:$G$324,1),$G$5:$G$324,0)) -> 767423.74 | H329: =LARGE($G$5:$G$324,1) -> 103513.66
A330: 2 | B330: =INDEX($A$5:$A$324,MATCH(LARGE($G$5:$G$324,2),$G$5:$G$324,0)) -> STR-1069 | C330: =INDEX($B$5:$B$324,MATCH(LARGE($G$5:$G$324,2),$G$5:$G$324,0)) -> 45748 | D330: =INDEX($D$5:$D$324,MATCH(LARGE($G$5:$G$324,2),$G$5:$G$324,0)) -> High Street | E330: =INDEX($C$5:$C$324,MATCH(LARGE($G$5:$G$324,2),$G$5:$G$324,0)) -> West | F330: =INDEX($E$5:$E$324,MATCH(LARGE($G$5:$G$324,2),$G$5:$G$324,0)) -> 686737.87 | G330: =INDEX($F$5:$F$324,MATCH(LARGE($G$5:$G$324,2),$G$5:$G$324,0)) -> 589093.17 | H330: =LARGE($G$5:$G$324,2) -> 97644.697
A331: 3 | B331: =INDEX($A$5:$A$324,MATCH(LARGE($G$5:$G$324,3),$G$5:$G$324,0)) -> STR-1030 | C331: =INDEX($B$5:$B$324,MATCH(LARGE($G$5:$G$324,3),$G$5:$G$324,0)) -> 45689 | D331: =INDEX($D$5:$D$324,MATCH(LARGE($G$5:$G$324,3),$G$5:$G$324,0)) -> Residential | E331: =INDEX($C$5:$C$324,MATCH(LARGE($G$5:$G$324,3),$G$5:$G$324,0)) -> West | F331: =INDEX($E$5:$E$324,MATCH(LARGE($G$5:$G$324,3),$G$5:$G$324,0)) -> 820519.04 | G331: =INDEX($F$5:$F$324,MATCH(LARGE($G$5:$G$324,3),$G$5:$G$324,0)) -> 728663.96 | H331: =LARGE($G$5:$G$324,3) -> 91855.078
A332: 4 | B332: =INDEX($A$5:$A$324,MATCH(LARGE($G$5:$G$324,4),$G$5:$G$324,0)) -> STR-1028 | C332: =INDEX($B$5:$B$324,MATCH(LARGE($G$5:$G$324,4),$G$5:$G$324,0)) -> 45748 | D332: =INDEX($D$5:$D$324,MATCH(LARGE($G$5:$G$324,4),$G$5:$G$324,0)) -> Mall | E332: =INDEX($C$5:$C$324,MATCH(LARGE($G$5:$G$324,4),$G$5:$G$324,0)) -> East | F332: =INDEX($E$5:$E$324,MATCH(LARGE($G$5:$G$324,4),$G$5:$G$324,0)) -> 713611.16 | G332: =INDEX($F$5:$F$324,MATCH(LARGE($G$5:$G$324,4),$G$5:$G$324,0)) -> 623402.39 | H332: =LARGE($G$5:$G$324,4) -> 90208.773
A333: 5 | B333: =INDEX($A$5:$A$324,MATCH(LARGE($G$5:$G$324,5),$G$5:$G$324,0)) -> STR-1059 | C333: =INDEX($B$5:$B$324,MATCH(LARGE($G$5:$G$324,5),$G$5:$G$324,0)) -> 45689 | D333: =INDEX($D$5:$D$324,MATCH(LARGE($G$5:$G$324,5),$G$5:$G$324,0)) -> Residential | E333: =INDEX($C$5:$C$324,MATCH(LARGE($G$5:$G$324,5),$G$5:$G$324,0)) -> West | F333: =INDEX($E$5:$E$324,MATCH(LARGE($G$5:$G$324,5),$G$5:$G$324,0)) -> 723305.11 | G333: =INDEX($F$5:$F$324,MATCH(LARGE($G$5:$G$324,5),$G$5:$G$324,0)) -> 636465.65 | H333: =LARGE($G$5:$G$324,5) -> 86839.462
A336: Top 5 Largest NEGATIVE Residuals (model over-predicts — actual sales fall short of prediction)
A337: Rank | B337: store_id | C337: month | D337: store_type | E337: region | F337: monthly_sales | G337: predicted_sales | H337: residual
A338: 1 | B338: =INDEX($A$5:$A$324,MATCH(SMALL($G$5:$G$324,1),$G$5:$G$324,0)) -> STR-1023 | C338: =INDEX($B$5:$B$324,MATCH(SMALL($G$5:$G$324,1),$G$5:$G$324,0)) -> 45689 | D338: =INDEX($D$5:$D$324,MATCH(SMALL($G$5:$G$324,1),$G$5:$G$324,0)) -> Mall | E338: =INDEX($C$5:$C$324,MATCH(SMALL($G$5:$G$324,1),$G$5:$G$324,0)) -> South | F338: =INDEX($E$5:$E$324,MATCH(SMALL($G$5:$G$324,1),$G$5:$G$324,0)) -> 627171.9 | G338: =INDEX($F$5:$F$324,MATCH(SMALL($G$5:$G$324,1),$G$5:$G$324,0)) -> 765254.56 | H338: =SMALL($G$5:$G$324,1) -> -138082.66
A339: 2 | B339: =INDEX($A$5:$A$324,MATCH(SMALL($G$5:$G$324,2),$G$5:$G$324,0)) -> STR-1017 | C339: =INDEX($B$5:$B$324,MATCH(SMALL($G$5:$G$324,2),$G$5:$G$324,0)) -> 45717 | D339: =INDEX($D$5:$D$324,MATCH(SMALL($G$5:$G$324,2),$G$5:$G$324,0)) -> High Street | E339: =INDEX($C$5:$C$324,MATCH(SMALL($G$5:$G$324,2),$G$5:$G$324,0)) -> West | F339: =INDEX($E$5:$E$324,MATCH(SMALL($G$5:$G$324,2),$G$5:$G$324,0)) -> 685379.08 | G339: =INDEX($F$5:$F$324,MATCH(SMALL($G$5:$G$324,2),$G$5:$G$324,0)) -> 803619.66 | H339: =SMALL($G$5:$G$324,2) -> -118240.58
A340: 3 | B340: =INDEX($A$5:$A$324,MATCH(SMALL($G$5:$G$324,3),$G$5:$G$324,0)) -> STR-1068 | C340: =INDEX($B$5:$B$324,MATCH(SMALL($G$5:$G$324,3),$G$5:$G$324,0)) -> 45658 | D340: =INDEX($D$5:$D$324,MATCH(SMALL($G$5:$G$324,3),$G$5:$G$324,0)) -> Mall | E340: =INDEX($C$5:$C$324,MATCH(SMALL($G$5:$G$324,3),$G$5:$G$324,0)) -> East | F340: =INDEX($E$5:$E$324,MATCH(SMALL($G$5:$G$324,3),$G$5:$G$324,0)) -> 660633.99 | G340: =INDEX($F$5:$F$324,MATCH(SMALL($G$5:$G$324,3),$G$5:$G$324,0)) -> 761573.66 | H340: =SMALL($G$5:$G$324,3) -> -100939.67
A341: 4 | B341: =INDEX($A$5:$A$324,MATCH(SMALL($G$5:$G$324,4),$G$5:$G$324,0)) -> STR-1012 | C341: =INDEX($B$5:$B$324,MATCH(SMALL($G$5:$G$324,4),$G$5:$G$324,0)) -> 45658 | D341: =INDEX($D$5:$D$324,MATCH(SMALL($G$5:$G$324,4),$G$5:$G$324,0)) -> Residential | E341: =INDEX($C$5:$C$324,MATCH(SMALL($G$5:$G$324,4),$G$5:$G$324,0)) -> West | F341: =INDEX($E$5:$E$324,MATCH(SMALL($G$5:$G$324,4),$G$5:$G$324,0)) -> 595467.6 | G341: =INDEX($F$5:$F$324,MATCH(SMALL($G$5:$G$324,4),$G$5:$G$324,0)) -> 691725.12 | H341: =SMALL($G$5:$G$324,4) -> -96257.519
A342: 5 | B342: =INDEX($A$5:$A$324,MATCH(SMALL($G$5:$G$324,5),$G$5:$G$324,0)) -> STR-1007 | C342: =INDEX($B$5:$B$324,MATCH(SMALL($G$5:$G$324,5),$G$5:$G$324,0)) -> 45689 | D342: =INDEX($D$5:$D$324,MATCH(SMALL($G$5:$G$324,5),$G$5:$G$324,0)) -> Mall | E342: =INDEX($C$5:$C$324,MATCH(SMALL($G$5:$G$324,5),$G$5:$G$324,0)) -> West | F342: =INDEX($E$5:$E$324,MATCH(SMALL($G$5:$G$324,5),$G$5:$G$324,0)) -> 800451.94 | G342: =INDEX($F$5:$F$324,MATCH(SMALL($G$5:$G$324,5),$G$5:$G$324,0)) -> 895528.45 | H342: =SMALL($G$5:$G$324,5) -> -95076.509

Sheet Model_Comparison
A1: Model Comparison — All Regression Models
A2: Live comparison pulling R-squared, key coefficient, and significance directly from each model sheet.
A4: Model | B4: Type | C4: Key Variable(s) | D4: R-squared | E4: Adj. R-squared | F4: P-value (key var) | G4: N
A5: Simple Model 1 | B5: Simple | C5: marketing_spend | D5: =Simple_Regression!B14 -> 0.16724469 | E5: n/a | F5: =Simple_Regression!B18 -> 2.4800615e-14 | G5: 320
A6: Simple Model 2 | B6: Simple | C6: footfall | D6: =Simple_Regression!B33 -> 0.73628534 | E6: n/a | F6: =Simple_Regression!B37 -> 4.7503615e-94 | G6: 320
A7: Simple Model 3 | B7: Simple | C7: avg_discount_pct | D7: =Simple_Regression!B52 -> 0.008290503 | E7: n/a | F7: =Simple_Regression!B56 -> 0.10399305 | G7: 320
A8: Model A (Full) | B8: Multiple | C8: 11 predictors incl. staff_count | D8: =Multiple_Regression!B27 -> 0.84699062 | E8: =Multiple_Regression!B28 -> 0.841526 | F8: see coef. table | G8: 320
A9: Model B (FINAL) | B9: Multiple | C9: 10 predictors (drops staff_count) | D9: =Multiple_Regression!B56 -> 0.84305383 | E9: =Multiple_Regression!B57 -> 0.83797467 | F9: see coef. table | G9: 320
A11: Full written comparison (business usefulness, significant variables, limitations) is in analysis/model_comparison.md.
A12: Final model selected: Model B — see outputs/model_equations.md for the full equation and reasoning.
